<?xml version="1.0" encoding="utf-8"?>
<robot xmlns:xacro="http://www.ros.org/wiki/xacro" name="dronut">

<xacro:include filename="$(find realsense_cam)/urdf/test_d455_camera.urdf.xacro"/>

<link name="part_9">
<visual>
<origin xyz="7.6327832942979512154e-17 -2.7755575615628913511e-17 0.085000000000000006106" rpy="-4.3368086899420129212e-19 -2.3418766925686843389e-17 4.5622041572063771955e-17" />
<geometry>
<mesh filename="file:///$(find dronut_description)/meshes/part_9.stl"/>
</geometry>
<material name="part_9_material">
<color rgba="0.91764705882352937127 0.91764705882352937127 0.91764705882352937127 1.0"/>
</material>
</visual>
<collision>
<origin xyz="7.6327832942979512154e-17 -2.7755575615628913511e-17 0.085000000000000006106" rpy="-4.3368086899420129212e-19 -2.3418766925686843389e-17 4.5622041572063771955e-17" />
<geometry>
<mesh filename="file:///$(find dronut_description)/meshes/part_9.stl"/>
</geometry>
</collision>
<inertial>
<origin xyz="3.3960968933820755655e-17 -2.0547414943426984389e-17 0.0074999999999999233946" rpy="0 0 0"/>
<mass value="0.051373957375585505014" />
<inertia ixx="7.6423108565933732506e-05" ixy="6.9731564721227397869e-21"  ixz="5.2878801023991200047e-21" iyy="7.6423108565933637638e-05" iyz="-9.7923705599983600173e-23" izz="0.00014937358342808888887" />
</inertial>
</link>

<link name="part_14">
<visual>
<origin xyz="-1.232595164407830946e-32 4.6213854812636437596e-19 -0.072100000000000011302" rpy="3.141592653589793116 -0 -1.0965011304470282907e-34" />
<geometry>
<mesh filename="file:///$(find dronut_description)/meshes/part_14.stl"/>
</geometry>
<material name="part_14_material">
<color rgba="0.91764705882352937127 0.91764705882352937127 0.91764705882352937127 1.0"/>
</material>
</visual>
<collision>
<origin xyz="-1.232595164407830946e-32 4.6213854812636437596e-19 -0.072100000000000011302" rpy="3.141592653589793116 -0 -1.0965011304470282907e-34" />
<geometry>
<mesh filename="file:///$(find dronut_description)/meshes/part_14.stl"/>
</geometry>
</collision>
<inertial>
<origin xyz="6.7721465973631873756e-18 8.9453058408210748898e-18 0.0055085776757560628303" rpy="0 0 0"/>
<mass value="0.081361932183136378982" />
<inertia ixx="4.6732045507367330221e-05" ixy="-5.0714381474165955565e-39"  ixz="1.707345612856906361e-38" iyy="4.6732045507367323445e-05" iyz="6.8293824514276254441e-38" izz="8.8650452620701349071e-05" />
</inertial>
</link>

<link name="part_15">
<visual>
<origin xyz="-1.232595164407830946e-32 4.6213854812636129447e-19 -0.052100000000000014355" rpy="3.141592653589793116 -0 4.7894242191208391027e-35" />
<geometry>
<mesh filename="file:///$(find dronut_description)/meshes/part_15.stl"/>
</geometry>
<material name="part_15_material">
<color rgba="1 0.7568627450980391913 0.054901960784313724728 1.0"/>
</material>
</visual>
<collision>
<origin xyz="-1.232595164407830946e-32 4.6213854812636129447e-19 -0.052100000000000014355" rpy="3.141592653589793116 -0 4.7894242191208391027e-35" />
<geometry>
<mesh filename="file:///$(find dronut_description)/meshes/part_15.stl"/>
</geometry>
</collision>
<inertial>
<origin xyz="7.9196527012409534407e-05 0.00016558157467577814138 0.0074999027995096834154" rpy="0 0 0"/>
<mass value="0.026213211695048595218" />
<inertia ixx="6.9774478617537908959e-06" ixy="-6.9419266273694232071e-08"  ixz="-1.6609996238008518527e-11" iyy="6.9192015799699294629e-06" iyz="5.6588083614009351177e-11" izz="1.2913365664510818319e-05" />
</inertial>
</link>

<joint name="bottom_prop_continuous" type="continuous">
<origin xyz="-1.364188843237277732e-17 8.9470061809509301176e-19 -0.020000000000000003886" rpy="-1.5043718997413332303e-17 3.2066320222166132166e-17 2.6618398979288904194" />
<parent link="part_14" />
<child link="part_15" />
<axis xyz="0 0 1"/>
<limit effort="1" velocity="20" />
<joint_properties friction="0.0"/>
</joint>

<joint name="base_link_bod" type="fixed">
<origin xyz="9.0111815578830527523e-17 -2.694948477030324967e-17 0.012499999999999997224" rpy="-3.141592653589793116 -2.2985086056692669349e-17 4.2131418796428849561e-17" />
<parent link="part_9" />
<child link="part_14" />
<axis xyz="0 0 1"/>
<limit effort="1" velocity="20" />
<joint_properties friction="0.0"/>
</joint>

<link name="part_12">
<visual>
<origin xyz="-0.045293116147792883419 -0.070000000000000006661 -3.4694469519536111073e-18" rpy="1.570796326794896558 1.7763568394002504647e-15 0" />
<geometry>
<mesh filename="file:///$(find dronut_description)/meshes/part_12.stl"/>
</geometry>
<material name="part_12_material">
<color rgba="0.91764705882352937127 0.91764705882352937127 0.91764705882352937127 1.0"/>
</material>
</visual>
<collision>
<origin xyz="-0.045293116147792883419 -0.070000000000000006661 -3.4694469519536111073e-18" rpy="1.570796326794896558 1.7763568394002504647e-15 0" />
<geometry>
<mesh filename="file:///$(find dronut_description)/meshes/part_12.stl"/>
</geometry>
</collision>
<inertial>
<origin xyz="0.016722101582252131557 -0.023732782600301274845 -0.00054190616347032840444" rpy="0 0 0"/>
<mass value="0.021501977351633429214" />
<inertia ixx="6.6948647036419057309e-06" ixy="2.7244976620582874213e-06"  ixz="4.4292879423564113717e-09" iyy="3.3482707250144158527e-06" iyz="-6.2510766272301817152e-08" izz="7.096661523469771712e-06" />
</inertial>
</link>

<link name="part_7">
<visual>
<origin xyz="-3.8841542829293196348e-17 -1.0130642336654330904e-17 -0.014999999999999999445" rpy="3.141592653589793116 -0 -1.2582491531201756932e-33" />
<geometry>
<mesh filename="file:///$(find dronut_description)/meshes/part_7.stl"/>
</geometry>
<material name="part_7_material">
<color rgba="0.91764705882352937127 0.91764705882352937127 0.91764705882352937127 1.0"/>
</material>
</visual>
<collision>
<origin xyz="-3.8841542829293196348e-17 -1.0130642336654330904e-17 -0.014999999999999999445" rpy="3.141592653589793116 -0 -1.2582491531201756932e-33" />
<geometry>
<mesh filename="file:///$(find dronut_description)/meshes/part_7.stl"/>
</geometry>
</collision>
<inertial>
<origin xyz="1.9789404283332753899e-18 3.0814879110195773649e-33 -0.0074999999999999997224" rpy="0 0 0"/>
<mass value="0.21791440406939460717" />
<inertia ixx="0.00064443766156405308827" ixy="-1.5613660678591771471e-36"  ixz="0" iyy="0.00064443766156405297985" iyz="0" izz="0.0012807035329755035811" />
</inertial>
</link>

<link name="part_2">
<visual>
<origin xyz="4.336808689942017736e-18 8.6736173798840354721e-19 -0.016899999999999998357" rpy="0 -0 2.9490802273429065764e-34" />
<geometry>
<mesh filename="file:///$(find dronut_description)/meshes/part_2.stl"/>
</geometry>
<material name="part_2_material">
<color rgba="0.91764705882352937127 0.91764705882352937127 0.91764705882352937127 1.0"/>
</material>
</visual>
<collision>
<origin xyz="4.336808689942017736e-18 8.6736173798840354721e-19 -0.016899999999999998357" rpy="0 -0 2.9490802273429065764e-34" />
<geometry>
<mesh filename="file:///$(find dronut_description)/meshes/part_2.stl"/>
</geometry>
</collision>
<inertial>
<origin xyz="3.3664903194803088753e-18 9.5361225980722206553e-19 -0.0084499999999999991784" rpy="0 0 0"/>
<mass value="0.024954329648975794032" />
<inertia ixx="2.8477472090821188981e-06" ixy="2.7942984511615877618e-37"  ixz="0" iyy="2.8477472090821193216e-06" iyz="0" izz="4.507626736323575317e-06" />
</inertial>
</link>

<link name="part_5">
<visual>
<origin xyz="0.019007106887148045304 -0.016899999999999970601 4.973777466277251591e-18" rpy="-1.570796326794896558 -1.1466732054050117195 5.990425320549287883e-32" />
<geometry>
<mesh filename="file:///$(find dronut_description)/meshes/part_5.stl"/>
</geometry>
<material name="part_5_material">
<color rgba="0.91764705882352937127 0.91764705882352937127 0.91764705882352937127 1.0"/>
</material>
</visual>
<collision>
<origin xyz="0.019007106887148045304 -0.016899999999999970601 4.973777466277251591e-18" rpy="-1.570796326794896558 -1.1466732054050117195 5.990425320549287883e-32" />
<geometry>
<mesh filename="file:///$(find dronut_description)/meshes/part_5.stl"/>
</geometry>
</collision>
<inertial>
<origin xyz="-0.014158742125619390093 -0.0084500106947510058436 0.015936687035204354784" rpy="0 0 0"/>
<mass value="0.01269687389112876888" />
<inertia ixx="1.2149598618255739965e-06" ixy="1.2433638112913800777e-11"  ixz="8.4475228348310668446e-07" iyy="2.1948704880735051315e-06" iyz="-1.822396760172554942e-11" izz="1.5843126851911382545e-06" />
</inertial>
</link>

<joint name="des1" type="fixed">
<origin xyz="-0.0078218379446664248328 -0.01732307603709132629 0" rpy="1.570796326794896558 -9.1544181216245329449e-18 1.1466732054050212675" />
<parent link="part_2" />
<child link="part_5" />
<axis xyz="0 0 1"/>
<limit effort="1" velocity="20" />
<joint_properties friction="0.0"/>
</joint>

<link name="part_4">
<visual>
<origin xyz="0.019007106887148045304 -0.016899999999999984479 4.526544070126981012e-18" rpy="-1.570796326794896558 0.36127504200756288544 -1.778832635448547917e-31" />
<geometry>
<mesh filename="file:///$(find dronut_description)/meshes/part_4.stl"/>
</geometry>
<material name="part_4_material">
<color rgba="0.91764705882352937127 0.91764705882352937127 0.91764705882352937127 1.0"/>
</material>
</visual>
<collision>
<origin xyz="0.019007106887148045304 -0.016899999999999984479 4.526544070126981012e-18" rpy="-1.570796326794896558 0.36127504200756288544 -1.778832635448547917e-31" />
<geometry>
<mesh filename="file:///$(find dronut_description)/meshes/part_4.stl"/>
</geometry>
</collision>
<inertial>
<origin xyz="-0.015328229622304786334 -0.0084499872669267523523 0.014380624838855953287" rpy="0 0 0"/>
<mass value="0.012120372023565320618" />
<inertia ixx="9.8370132492095895133e-07" ixy="-7.8691653975887320142e-12"  ixz="7.4435299128569697565e-07" iyy="2.0241721495233889767e-06" iyz="5.0301847615442548021e-12" izz="1.6174332040731001351e-06" />
</inertial>
</link>

<joint name="des2" type="fixed">
<origin xyz="-0.017780139188853304882 0.006718389884821580546 0" rpy="1.570796326794896558 1.8302242157616762217e-18 -0.36127504200756299646" />
<parent link="part_2" />
<child link="part_4" />
<axis xyz="0 0 1"/>
<limit effort="1" velocity="20" />
<joint_properties friction="0.0"/>
</joint>

<link name="part_6">
<visual>
<origin xyz="-0.019007106887148045304 0.016899999999999984479 -2.1345230270808368545e-18" rpy="1.570796326794896558 -0.36127504200756388464 -1.5482432197422550821e-31" />
<geometry>
<mesh filename="file:///$(find dronut_description)/meshes/part_6.stl"/>
</geometry>
<material name="part_6_material">
<color rgba="0.91764705882352937127 0.91764705882352937127 0.91764705882352937127 1.0"/>
</material>
</visual>
<collision>
<origin xyz="-0.019007106887148045304 0.016899999999999984479 -2.1345230270808368545e-18" rpy="1.570796326794896558 -0.36127504200756388464 -1.5482432197422550821e-31" />
<geometry>
<mesh filename="file:///$(find dronut_description)/meshes/part_6.stl"/>
</geometry>
</collision>
<inertial>
<origin xyz="0.015323673517964059992 0.0084499948978207194139 0.014316773764147732589" rpy="0 0 0"/>
<mass value="0.012216688553059231945" />
<inertia ixx="9.9643460653752272962e-07" ixy="-1.0753815192782883456e-11"  ixz="-7.4996920162103364967e-07" iyy="2.0411543484748433149e-06" iyz="-4.7026239216436038486e-12" izz="1.6262672275786188102e-06" />
</inertial>
</link>

<joint name="des3" type="fixed">
<origin xyz="0.017780139188853325699 -0.006718389884821577944 4.1633363423443370266e-17" rpy="-1.570796326794896558 1.0838106842553144622e-19 -0.36127504200756394015" />
<parent link="part_2" />
<child link="part_6" />
<axis xyz="0 0 1"/>
<limit effort="1" velocity="20" />
<joint_properties friction="0.0"/>
</joint>

<link name="part_3">
<visual>
<origin xyz="-0.019007106887148045304 0.016899999999999998357 2.8460307027744491393e-19" rpy="1.570796326794896558 1.1466732054050117195 -8.2368348157552691969e-32" />
<geometry>
<mesh filename="file:///$(find dronut_description)/meshes/part_3.stl"/>
</geometry>
<material name="part_3_material">
<color rgba="0.91764705882352937127 0.91764705882352937127 0.91764705882352937127 1.0"/>
</material>
</visual>
<collision>
<origin xyz="-0.019007106887148045304 0.016899999999999998357 2.8460307027744491393e-19" rpy="1.570796326794896558 1.1466732054050117195 -8.2368348157552691969e-32" />
<geometry>
<mesh filename="file:///$(find dronut_description)/meshes/part_3.stl"/>
</geometry>
</collision>
<inertial>
<origin xyz="0.014158634178683113247 0.0084500106949858787286 0.015936716490248640371" rpy="0 0 0"/>
<mass value="0.012696595092807082955" />
<inertia ixx="1.2148986685475899047e-06" ixy="1.9339197372822625489e-11"  ixz="-8.4462799691268726169e-07" iyy="2.1945433423718527668e-06" iyz="2.1342025230313500647e-11" izz="1.5840228444908738692e-06" />
</inertial>
</link>

<joint name="des4" type="fixed">
<origin xyz="0.0078218379446664352411 0.01732307603709126731 2.7755575615628913511e-17" rpy="-1.570796326794896558 -2.3306571988709510217e-19 1.1466732054050119416" />
<parent link="part_2" />
<child link="part_3" />
<axis xyz="0 0 1"/>
<limit effort="1" velocity="20" />
<joint_properties friction="0.0"/>
</joint>

<link name="part_8">
<visual>
<origin xyz="3.4829994791096829942e-18 -6.9388939039072283776e-18 0" rpy="0 -0 -3.6498224437122495693e-33" />
<geometry>
<mesh filename="file:///$(find dronut_description)/meshes/part_8.stl"/>
</geometry>
<material name="part_8_material">
<color rgba="1 0.7568627450980391913 0.054901960784313724728 1.0"/>
</material>
</visual>
<collision>
<origin xyz="3.4829994791096829942e-18 -6.9388939039072283776e-18 0" rpy="0 -0 -3.6498224437122495693e-33" />
<geometry>
<mesh filename="file:///$(find dronut_description)/meshes/part_8.stl"/>
</geometry>
</collision>
<inertial>
<origin xyz="1.8282570853372088999e-05 -0.00020558706347334468529 -0.0158628605053490572" rpy="0 0 0"/>
<mass value="0.05643575641925743791" />
<inertia ixx="1.3710625894635967352e-05" ixy="3.8424605010663454723e-08"  ixz="7.4910713722498708457e-09" iyy="1.3556858018073300248e-05" iyz="-7.6392449079404456055e-08" izz="1.8884521296182718087e-05" />
</inertial>
</link>

<joint name="top_prop_continuous" type="continuous">
<origin xyz="1.0408340855860842566e-17 8.6736173798839122125e-19 -0.016899999999999998357" rpy="-7.3916867149447724515e-15 3.2485461318883792865e-16 -2.3830289412780203244e-15" />
<parent link="part_2" />
<child link="part_8" />
<axis xyz="0 0 1"/>
<limit effort="1" velocity="20" />
<joint_properties friction="0.0"/>
</joint>

<link name="part_1">
<visual>
<origin xyz="1.6818686200681387533e-17 -2.5723220645108491003e-17 0.0084500000000000130562" rpy="3.141592653589793116 -0 -3.6863502841786867827e-34" />
<geometry>
<mesh filename="file:///$(find dronut_description)/meshes/part_1.stl"/>
</geometry>
<material name="part_1_material">
<color rgba="0.91764705882352937127 0.91764705882352937127 0.91764705882352937127 1.0"/>
</material>
</visual>
<collision>
<origin xyz="1.6818686200681387533e-17 -2.5723220645108491003e-17 0.0084500000000000130562" rpy="3.141592653589793116 -0 -3.6863502841786867827e-34" />
<geometry>
<mesh filename="file:///$(find dronut_description)/meshes/part_1.stl"/>
</geometry>
</collision>
<inertial>
<origin xyz="1.2891294033462901782e-17 -4.9927457578120581384e-17 1.3877787807814456755e-17" rpy="0 0 0"/>
<mass value="0.24551689525151818017" />
<inertia ixx="0.00072730649694726669501" ixy="1.778284931233923781e-38"  ixz="0" iyy="0.00072730649694726658659" iyz="0" izz="0.0014429259804857358547" />
</inertial>
</link>

<joint name="top_connect" type="fixed">
<origin xyz="-4.2825985813177425143e-18 -5.2655908495864328975e-17 -0.009999999999999995004" rpy="-3.1415926535897895633 -3.2663771856807971111e-31 -2.3801625817840493146e-18" />
<parent link="part_2" />
<child link="part_1" />
<axis xyz="0 0 1"/>
<limit effort="1" velocity="20" />
<joint_properties friction="0.0"/>
</joint>

<joint name="top_body_top" type="fixed">
<origin xyz="-7.5406261096366833385e-17 1.9631018211418146363e-17 -0.032499999999999945599" rpy="3.1415926535897895633 -7.2424705122032041318e-17 1.4611572450020903978e-16" />
<parent link="part_7" />
<child link="part_2" />
<axis xyz="0 0 1"/>
<limit effort="1" velocity="20" />
<joint_properties friction="0.0"/>
</joint>

<joint name="pillar_conn" type="fixed">
<origin xyz="-0.045186811173276476838 -0.054999999999999951705 1.5305873096246679236e-17" rpy="-1.570796326794896558 1.6277652375952179678e-15 -7.3292066860019927176e-17" />
<parent link="part_12" />
<child link="part_7" />
<axis xyz="0 0 1"/>
<limit effort="1" velocity="20" />
<joint_properties friction="0.0"/>
</joint>

<joint name="pillar1" type="fixed">
<origin xyz="0.045293116147793056891 5.7983096687068549328e-17 0.0150000000000000272" rpy="-1.570796326794896558 -2.341876692568686496e-17 1.8150332108048290725e-15" />
<parent link="part_9" />
<child link="part_12" />
<axis xyz="0 0 1"/>
<limit effort="1" velocity="20" />
<joint_properties friction="0.0"/>
</joint>

<link name="part_11">
<visual>
<origin xyz="0.045293116147792883419 0.070000000000000006661 -6.9388939039072037257e-18" rpy="-1.570796326794896558 -1.5707963267948954478 0" />
<geometry>
<mesh filename="file:///$(find dronut_description)/meshes/part_11.stl"/>
</geometry>
<material name="part_11_material">
<color rgba="0.91764705882352937127 0.91764705882352937127 0.91764705882352937127 1.0"/>
</material>
</visual>
<collision>
<origin xyz="0.045293116147792883419 0.070000000000000006661 -6.9388939039072037257e-18" rpy="-1.570796326794896558 -1.5707963267948954478 0" />
<geometry>
<mesh filename="file:///$(find dronut_description)/meshes/part_11.stl"/>
</geometry>
</collision>
<inertial>
<origin xyz="-0.016721189848875085693 0.02373262998480587388 0.00054186663619865496101" rpy="0 0 0"/>
<mass value="0.021502171507728148198" />
<inertia ixx="6.6957576039926302458e-06" ixy="2.7248599227897574702e-06"  ixz="4.4433573060991138994e-09" iyy="3.3491885845905642225e-06" iyz="-6.2517612404777603218e-08" izz="7.0968211888740793033e-06" />
</inertial>
</link>

<joint name="pillar2" type="fixed">
<origin xyz="6.8398038396621346516e-17 -0.045293116147792987503 0.0150000000000000272" rpy="1.570796326794896558 -2.68882138776405038e-17 1.570796326794896336" />
<parent link="part_9" />
<child link="part_11" />
<axis xyz="0 0 1"/>
<limit effort="1" velocity="20" />
<joint_properties friction="0.0"/>
</joint>

<link name="part_10">
<visual>
<origin xyz="0.045293116147792883419 0.070000000000000006661 -5.2041704279304182017e-18" rpy="-1.570796326794896558 1.8988215193149860073e-15 0" />
<geometry>
<mesh filename="file:///$(find dronut_description)/meshes/part_10.stl"/>
</geometry>
<material name="part_10_material">
<color rgba="0.91764705882352937127 0.91764705882352937127 0.91764705882352937127 1.0"/>
</material>
</visual>
<collision>
<origin xyz="0.045293116147792883419 0.070000000000000006661 -5.2041704279304182017e-18" rpy="-1.570796326794896558 1.8988215193149860073e-15 0" />
<geometry>
<mesh filename="file:///$(find dronut_description)/meshes/part_10.stl"/>
</geometry>
</collision>
<inertial>
<origin xyz="-0.01672210402384891742 0.02373279116346218437 0.00054187169411183634324" rpy="0 0 0"/>
<mass value="0.021501965922627864353" />
<inertia ixx="6.6950435970853901593e-06" ixy="2.7245022319351075036e-06"  ixz="4.4323430964400336135e-09" iyy="3.3484587220224330101e-06" iyz="-6.2515666220294563553e-08" izz="7.0966768263434284143e-06" />
</inertial>
</link>

<joint name="pillar3" type="fixed">
<origin xyz="-0.045293116147792890358 5.1134843763975085258e-17 0.0150000000000000272" rpy="1.570796326794896558 -2.2985086056692675512e-17 -1.8566748539255061366e-15" />
<parent link="part_9" />
<child link="part_10" />
<axis xyz="0 0 1"/>
<limit effort="1" velocity="20" />
<joint_properties friction="0.0"/>
</joint>

<link name="part_13">
<visual>
<origin xyz="-0.045293116147792890358 -0.070000000000000006661 -1.7347234759768070944e-18" rpy="1.570796326794896558 1.5707963267948961139 0" />
<geometry>
<mesh filename="file:///$(find dronut_description)/meshes/part_13.stl"/>
</geometry>
<material name="part_13_material">
<color rgba="0.91764705882352937127 0.91764705882352937127 0.91764705882352937127 1.0"/>
</material>
</visual>
<collision>
<origin xyz="-0.045293116147792890358 -0.070000000000000006661 -1.7347234759768070944e-18" rpy="1.570796326794896558 1.5707963267948961139 0" />
<geometry>
<mesh filename="file:///$(find dronut_description)/meshes/part_13.stl"/>
</geometry>
</collision>
<inertial>
<origin xyz="0.016968989830426384202 -0.023215211261650249563 -0.00045893043881087985675" rpy="0 0 0"/>
<mass value="0.018905727878865487973" />
<inertia ixx="5.8199034220071030999e-06" ixy="2.5377557635465456971e-06"  ixz="3.4097512175846834347e-08" iyy="2.7699823799042757312e-06" iyz="-2.60203049854022428e-08" izz="6.5242197443933042735e-06" />
</inertial>
</link>

<joint name="pillar4" type="fixed">
<origin xyz="8.2300098248377027912e-17 0.045293116147792911175 0.0150000000000000272" rpy="-1.570796326794896558 4.3368086899420369953e-19 1.570796326794896336" />
<parent link="part_9" />
<child link="part_13" />
<axis xyz="0 0 1"/>
<limit effort="1" velocity="20" />
<joint_properties friction="0.0"/>
</joint>

<link name="part_18">
<visual>
<origin xyz="3.6862873864507150756e-18 1.9081958235744890364e-17 0.040000000000000007772" rpy="0 -7.7037197775489434122e-34 -3.7239661034049977378e-35" />
<geometry>
<mesh filename="file:///$(find dronut_description)/meshes/part_18.stl"/>
</geometry>
<material name="part_18_material">
<color rgba="0.91764705882352937127 0.91764705882352937127 0.91764705882352937127 1.0"/>
</material>
</visual>
<collision>
<origin xyz="3.6862873864507150756e-18 1.9081958235744890364e-17 0.040000000000000007772" rpy="0 -7.7037197775489434122e-34 -3.7239661034049977378e-35" />
<geometry>
<mesh filename="file:///$(find dronut_description)/meshes/part_18.stl"/>
</geometry>
</collision>
<inertial>
<origin xyz="0.027653116040894293315 -0.028314594608833801304 6.9388939039072283776e-18" rpy="0 0 0"/>
<mass value="0.012037753032263794062" />
<inertia ixx="3.5554734251893729991e-06" ixy="-1.8015690025981952452e-06"  ixz="2.7390370944181056457e-39" iyy="3.5569104064419149182e-06" iyz="-1.3878782755934840531e-39" izz="3.9023163563609431146e-06" />
</inertial>
</link>

<joint name="slider_front" type="prismatic">
<origin xyz="1.2347761702002914081e-16 -8.6977309035618530899e-17 0.022430000000000005489" rpy="-2.2551405187698405946e-17 -4.770489558936214117e-18 1.570796326794896558" />
<parent link="part_9" />
<child link="part_18" />
<axis xyz="0 0 1"/>
<limit effort="1" velocity="20" lower="0.015" upper="0.041"/>
<joint_properties friction="0.0"/>
</joint>

<link name="part_17">
<visual>
<origin xyz="8.6736173798840354721e-19 6.3967928176644792421e-18 0.060000000000000011657" rpy="0 -0 8.5575988739861001759e-35" />
<geometry>
<mesh filename="file:///$(find dronut_description)/meshes/part_17.stl"/>
</geometry>
<material name="part_17_material">
<color rgba="0.91764705882352937127 0.91764705882352937127 0.91764705882352937127 1.0"/>
</material>
</visual>
<collision>
<origin xyz="8.6736173798840354721e-19 6.3967928176644792421e-18 0.060000000000000011657" rpy="0 -0 8.5575988739861001759e-35" />
<geometry>
<mesh filename="file:///$(find dronut_description)/meshes/part_17.stl"/>
</geometry>
</collision>
<inertial>
<origin xyz="-0.028798731671654986125 -0.026710851099630936178 0.020000000000000010825" rpy="0 0 0"/>
<mass value="0.012525165011287383784" />
<inertia ixx="3.9497003486092899124e-06" ixy="1.9945554830126215458e-06"  ixz="0" iyy="3.7436903366894957597e-06" iyz="0" izz="4.3533466822888187893e-06" />
</inertial>
</link>

<joint name="slider_back" type="prismatic">
<origin xyz="6.2776311926526772165e-17 2.0448052973076597602e-17 0.036080000000000014837" rpy="2.6454533008646252723e-17 5.6378512969245521826e-18 2.2954338760707362899e-16" />
<parent link="part_9" />
<child link="part_17" />
<axis xyz="0 0 1"/>
<limit effort="1" velocity="20" lower="-0.019" upper="0.008"/>
<joint_properties friction="0.0"/>
</joint>

<link name="part_16">
<visual>
<origin xyz="1.5178830414797062076e-17 4.7704895589362195096e-18 0.040000000000000007772" rpy="0 -0 1.0156271191104558723e-35" />
<geometry>
<mesh filename="file:///$(find dronut_description)/meshes/part_16.stl"/>
</geometry>
<material name="part_16_material">
<color rgba="0.91764705882352937127 0.91764705882352937127 0.91764705882352937127 1.0"/>
</material>
</visual>
<collision>
<origin xyz="1.5178830414797062076e-17 4.7704895589362195096e-18 0.040000000000000007772" rpy="0 -0 1.0156271191104558723e-35" />
<geometry>
<mesh filename="file:///$(find dronut_description)/meshes/part_16.stl"/>
</geometry>
</collision>
<inertial>
<origin xyz="-0.027179092950953519237 0.02917561889449950957 6.9388939039072283776e-18" rpy="0 0 0"/>
<mass value="0.011599122267313749166" />
<inertia ixx="3.2134387520874446969e-06" ixy="-1.6205824050960643482e-06"  ixz="0" iyy="3.3750794660311106063e-06" iyz="0" izz="3.495418946834892778e-06" />
</inertial>
</link>

<joint name="slider_left" type="prismatic">
<origin xyz="7.3121474153392539981e-17 -2.0789429205914076587e-17 0.022160000000000006082" rpy="-4.3368086899420129212e-19 -2.3418766925686846471e-17 4.5622041572063771955e-17" />
<parent link="part_9" />
<child link="part_16" />
<axis xyz="0 0 1"/>
<limit effort="1" velocity="20" lower="0.015" upper="0.041"/>
<joint_properties friction="0.0"/>
</joint>

<link name="part_19">
<visual>
<origin xyz="1.7347234759768070944e-18 3.4694469519536141888e-18 0.040000000000000007772" rpy="0 -0 -7.5231638452632267229e-36" />
<geometry>
<mesh filename="file:///$(find dronut_description)/meshes/part_19.stl"/>
</geometry>
<material name="part_19_material">
<color rgba="0.91764705882352937127 0.91764705882352937127 0.91764705882352937127 1.0"/>
</material>
</visual>
<collision>
<origin xyz="1.7347234759768070944e-18 3.4694469519536141888e-18 0.040000000000000007772" rpy="0 -0 -7.5231638452632267229e-36" />
<geometry>
<mesh filename="file:///$(find dronut_description)/meshes/part_19.stl"/>
</geometry>
</collision>
<inertial>
<origin xyz="0.027654374374672205383 0.028278492490992304664 0" rpy="0 0 0"/>
<mass value="0.012075499242470616457" />
<inertia ixx="3.5809281542651041055e-06" ixy="1.8171009461184530869e-06"  ixz="0" iyy="3.5770678690565939115e-06" iyz="0" izz="3.9378628919961947976e-06" />
</inertial>
</link>

<joint name="slider_right" type="prismatic">
    <origin xyz="8.0144224590128492692e-17 -2.1194452443085178714e-17 0.056060000000000012599" rpy="2.2551405187698396701e-17 8.6736173798847114735e-19 -1.570796326794896558" />
    <parent link="part_9" />
    <child link="part_19" />
    <axis xyz="0 0 1"/>
    <limit effort="1" velocity="20" lower="-0.018" upper="0.009"/>
    <joint_properties friction="0.0"/>
</joint>

<joint name="part_1_base_screw" type="fixed">
    <origin xyz="${0.07749} 0 0.0169" rpy="${3.141592653589793} 0 0"/>
    <parent link="part_1" />
    <child link="base_screw" />
    <axis xyz="0 0 1"/>
</joint>
<gazebo>
 <sensor name="dronut_cam" type="camera">
        <pose>0.01233 -0.03 .01878 0 0 0</pose>
        <camera>
          <image>
            <width>640</width>
            <height>480</height>
          </image>
          <clip>
            <near>0.1</near>
            <far>100</far>
          </clip>
          <distortion>
            <k1>1.578758331993112829e-01</k1>
            <k2>-5.784303605943902360e-01</k2>
            <k3>-8.740723680089258069e-03</k3>
            <p1>1.359451618091441112e-03</p1>
            <p2>1.640043376158566713e-01</p2>
            <center>0.5 0.5</center>
          </distortion>
          <lens>
            <type>pinhole</type>
            <scale_to_hfov>false</scale_to_hfov>
            <intrinsics>
              <fx>4.970870507466349295e+02</fx>
              <fy>4.976011127668800782e+02</fy>
              <cx>3.168387473166100108e+02</cx>
              <cy>2.342740555042151982e+02</cy>
              <s>0.0</s>
            </intrinsics>
          </lens>
        </camera>
        <always_on>1</always_on>
        <update_rate>30</update_rate>
        <visualize>true</visualize>
        <topic>camera</topic>
      </sensor>
</gazebo>
<ros2_control name="dronut" type="system">
    <hardware>
        <plugin>gz_ros2_control/GazeboSimSystem</plugin>
    </hardware>
    <joint name="bottom_prop_continuous">
        <command_interface name="position"/>
        <state_interface name="position"/>
    </joint>
    <joint name="top_prop_continuous">
        <command_interface name="position"/>
        <state_interface name="position"/>
    </joint>
    <joint name="slider_front">
        <command_interface name="position">
            <param name="min">0.015</param>
            <param name="max">0.041</param>
        </command_interface>
        <state_interface name="position"/>
    </joint>
    <joint name="slider_back">
        <command_interface name="position">
            <param name="min">-0.019</param>
            <param name="max">0.008</param>
        </command_interface>
        <state_interface name="position"/>
    </joint>
    <joint name="slider_left">
        <command_interface name="position">
            <param name="min">0.015</param>
            <param name="max">0.041</param>
        </command_interface>
        <state_interface name="position"/>
    </joint>
    <joint name="slider_right">
        <command_interface name="position">
            <param name="min">-0.018</param>
            <param name="max">0.009</param>
        </command_interface>
        <state_interface name="position"/>
    </joint>
</ros2_control>

<gazebo>
    <plugin filename="libgz_ros2_control-system" name="gz_ros2_control::GazeboSimROS2ControlPlugin">
        <parameters>$(find dronut_controller)/config/dronut_controllers.yaml</parameters>
            <ros>
                <remapping>/controller_manager/robot_description:=/robot_description</remapping>
            </ros>
    </plugin>
</gazebo>
</robot>
